Workbook
Name APC: Selections!$N$3:$N$9
Name AssetType: Selections!$A$3:$A$16
Name DCS: Selections!$C$3:$C$18
Name Historian: Selections!$O$3:$O$5
Name HMI: Selections!$P$3:$P$5
Name ManualInventory: Selections!$D$3
Name MISC: Selections!$E$3:$E$11
Name NetworkDevices: Selections!$F$3:$F$4
Name PLC: Selections!$G$3:$G$14
Name RTU: Selections!$I$3
Name SCADA: Selections!$J$3:$J$4
Name SIS: Selections!$K$3:$K$10
Name TCS: Selections!$L$3:$L$5
Name VMS: Selections!$M$3
Name WindowsDevices: Selections!$H$3

Sheet Instructions
A1: Required Columns: Company(1) and Site(2) For Three Levels: Utilize Unit (3) Column To Help Build Asset Naming: Utilize Sub-Area (4) Column (will not affect Asset Hierarchy) Input Asset Type (4) and Select Asset Model (5) Select Data Drive (6) Optionally, Review Asset Name and Update Asset Name Accordingly

Sheet Assets
A1: Input Company Name Level 1 (1) | B1: Input Site/Plant Level 2 (2) | C1: Input Units Level 3 (3) | D1: Input Sub-Area (Used to Build Asset Name) (Optional) | E1: Select Asset Type (4) | F1: Select Asset Model (5) | G1: Select Vendor Prefix (6) | H1: Select Product (7) | I1: Input Data Drive (8) | J1: Remove Formula and Enter Asset Prefix Manually, if Needed | K1: Remove Formula and Enter Asset Name Manually, if Needed | L1: Remove Formula and Enter Folder Name Manually, if Needed
A2: Company | B2: Plants | C2: Units | D2: Sub-Area | E2: Asset Type | F2: Asset Model | G2: Vendor Prefix | H2: Product | I2: Data Drive | J2: Asset Prefix | K2: Suggested Asset Naming | L2: Suggested Folder Naming | M2: MDIR Commands
B3: LAR | C3: CAR | E3: ManualInventory | F3: [Manual-Inventory] | G3: =_xlfn.IFNA(VLOOKUP(F3,'Look Table'!B$1:E$64,3,FALSE),"") -> PAS | H3: =_xlfn.IFNA(VLOOKUP(F3,'Look Table'!B$1:E$64,4,FALSE),"") -> ManualInventory | I3: D | J3: =_xlfn.TEXTJOIN("_",TRUE,B3:C3) -> LAR_CAR | K3: =J3&"_"&E3&IF(ISNUMBER(SEARCH("PAS",G3)),"","_")&(_xlfn.TEXTJOIN("_",TRUE,IF(G3 <> "PAS",G3:H3,""))&(IF(Table1[[#This Row],[Sub-Area]]<>"",_xlfn.CONCAT("_",Table1[[#This Row],[Sub-Area]]),""))) -> LAR_CAR_ManualInventory | L3: =IF(I3 <> "",I3&":\PAS\CBR\ProcessedFiles\"&Table1[[#This Row],[Units]]&"\"&Table1[[#This Row],[Asset Type]]&"\"&K3,"") -> D:\PAS\CBR\ProcessedFiles\CAR\ManualInventory\LAR_CAR_ManualInventory | M3: ="MKDIR "&Table1[[#This Row],[Suggested Folder Naming]] -> MKDIR D:\PAS\CBR\ProcessedFiles\CAR\ManualInventory\LAR_CAR_ManualInventory
B4: LAR | C4: WCC | E4: ManualInventory | F4: [Manual-Inventory] | G4: =_xlfn.IFNA(VLOOKUP(F4,'Look Table'!B$1:E$64,3,FALSE),"") -> PAS | H4: =_xlfn.IFNA(VLOOKUP(F4,'Look Table'!B$1:E$64,4,FALSE),"") -> ManualInventory | I4: D | J4: =_xlfn.TEXTJOIN("_",TRUE,B4:C4) -> LAR_WCC | K4: =J4&"_"&E4&IF(ISNUMBER(SEARCH("PAS",G4)),"","_")&(_xlfn.TEXTJOIN("_",TRUE,IF(G4 <> "PAS",G4:H4,""))&(IF(Table1[[#This Row],[Sub-Area]]<>"",_xlfn.CONCAT("_",Table1[[#This Row],[Sub-Area]]),""))) -> LAR_WCC_ManualInventory | L4: =IF(I4 <> "",I4&":\PAS\CBR\ProcessedFiles\"&Table1[[#This Row],[Units]]&"\"&Table1[[#This Row],[Asset Type]]&"\"&K4,"") -> D:\PAS\CBR\ProcessedFiles\WCC\ManualInventory\LAR_WCC_ManualInventory | M4: ="MKDIR "&Table1[[#This Row],[Suggested Folder Naming]] -> MKDIR D:\PAS\CBR\ProcessedFiles\WCC\ManualInventory\LAR_WCC_ManualInventory
B5: LAR | C5: WIL | E5: ManualInventory | F5: [Manual-Inventory] | G5: =_xlfn.IFNA(VLOOKUP(F5,'Look Table'!B$1:E$64,3,FALSE),"") -> PAS | H5: =_xlfn.IFNA(VLOOKUP(F5,'Look Table'!B$1:E$64,4,FALSE),"") -> ManualInventory | I5: D | J5: =_xlfn.TEXTJOIN("_",TRUE,B5:C5) -> LAR_WIL | K5: =J5&"_"&E5&IF(ISNUMBER(SEARCH("PAS",G5)),"","_")&(_xlfn.TEXTJOIN("_",TRUE,IF(G5 <> "PAS",G5:H5,""))&(IF(Table1[[#This Row],[Sub-Area]]<>"",_xlfn.CONCAT("_",Table1[[#This Row],[Sub-Area]]),""))) -> LAR_WIL_ManualInventory | L5: =IF(I5 <> "",I5&":\PAS\CBR\ProcessedFiles\"&Table1[[#This Row],[Units]]&"\"&Table1[[#This Row],[Asset Type]]&"\"&K5,"") -> D:\PAS\CBR\ProcessedFiles\WIL\ManualInventory\LAR_WIL_ManualInventory | M5: ="MKDIR "&Table1[[#This Row],[Suggested Folder Naming]] -> MKDIR D:\PAS\CBR\ProcessedFiles\WIL\ManualInventory\LAR_WIL_ManualInventory
B6: LAR | C6: CAR | D6: 17PLC_9057 | E6: PLC | F6: AB ControlLogix | G6: AB | H6: CtrLogix | I6: D | J6: =_xlfn.TEXTJOIN("_",TRUE,B6:C6) -> LAR_CAR | K6: =J6&"_"&E6&IF(ISNUMBER(SEARCH("PAS",G6)),"","_")&(_xlfn.TEXTJOIN("_",TRUE,IF(G6 <> "PAS",G6:H6,""))&(IF(Table1[[#This Row],[Sub-Area]]<>"",_xlfn.CONCAT("_",Table1[[#This Row],[Sub-Area]]),""))) -> LAR_CAR_PLC_AB_CtrLogix_17PLC_9057 | L6: =IF(I6 <> "",I6&":\PAS\CBR\ProcessedFiles\"&Table1[[#This Row],[Units]]&"\"&Table1[[#This Row],[Asset Type]]&"\"&K6,"") -> D:\PAS\CBR\ProcessedFiles\CAR\PLC\LAR_CAR_PLC_AB_CtrLogix_17PLC_9057 | M6: ="MKDIR "&Table1[[#This Row],[Suggested Folder Naming]] -> MKDIR D:\PAS\CBR\ProcessedFiles\CAR\PLC\LAR_CAR_PLC_AB_CtrLogix_17PLC_9057
B7: LAR | C7: CAR | D7: 17PLC_9057 | E7: PLC | F7: AB ControlLogix | G7: =_xlfn.IFNA(VLOOKUP(F7,'Look Table'!B$1:E$64,3,FALSE),"") -> AB | H7: =_xlfn.IFNA(VLOOKUP(F7,'Look Table'!B$1:E$64,4,FALSE),"") -> CtrLogix | I7: D | J7: =_xlfn.TEXTJOIN("_",TRUE,B7:C7) -> LAR_CAR | K7: =J7&"_"&E7&IF(ISNUMBER(SEARCH("PAS",G7)),"","_")&(_xlfn.TEXTJOIN("_",TRUE,IF(G7 <> "PAS",G7:H7,""))&(IF(Table1[[#This Row],[Sub-Area]]<>"",_xlfn.CONCAT("_",Table1[[#This Row],[Sub-Area]]),""))) -> LAR_CAR_PLC_AB_CtrLogix_17PLC_9057 | L7: =IF(I7 <> "",I7&":\PAS\CBR\ProcessedFiles\"&Table1[[#This Row],[Units]]&"\"&Table1[[#This Row],[Asset Type]]&"\"&K7,"") -> D:\PAS\CBR\ProcessedFiles\CAR\PLC\LAR_CAR_PLC_AB_CtrLogix_17PLC_9057 | M7: ="MKDIR "&Table1[[#This Row],[Suggested Folder Naming]] -> MKDIR D:\PAS\CBR\ProcessedFiles\CAR\PLC\LAR_CAR_PLC_AB_CtrLogix_17PLC_9057
B8: LAR | C8: CAR | D8: 61PLC_9337 | E8: PLC | F8: AB ControlLogix | G8: AB | H8: CtrLogix | I8: D | J8: =_xlfn.TEXTJOIN("_",TRUE,B8:C8) -> LAR_CAR | K8: =J8&"_"&E8&IF(ISNUMBER(SEARCH("PAS",G8)),"","_")&(_xlfn.TEXTJOIN("_",TRUE,IF(G8 <> "PAS",G8:H8,""))&(IF(Table1[[#This Row],[Sub-Area]]<>"",_xlfn.CONCAT("_",Table1[[#This Row],[Sub-Area]]),""))) -> LAR_CAR_PLC_AB_CtrLogix_61PLC_9337 | L8: =IF(I8 <> "",I8&":\PAS\CBR\ProcessedFiles\"&Table1[[#This Row],[Units]]&"\"&Table1[[#This Row],[Asset Type]]&"\"&K8,"") -> D:\PAS\CBR\ProcessedFiles\CAR\PLC\LAR_CAR_PLC_AB_CtrLogix_61PLC_9337 | M8: ="MKDIR "&Table1[[#This Row],[Suggested Folder Naming]] -> MKDIR D:\PAS\CBR\ProcessedFiles\CAR\PLC\LAR_CAR_PLC_AB_CtrLogix_61PLC_9337
B9: LAR | C9: CAR | D9: 61PLC_9347 | E9: PLC | F9: AB ControlLogix | G9: AB | H9: CtrLogix | I9: D | J9: =_xlfn.TEXTJOIN("_",TRUE,B9:C9) -> LAR_CAR | K9: =J9&"_"&E9&IF(ISNUMBER(SEARCH("PAS",G9)),"","_")&(_xlfn.TEXTJOIN("_",TRUE,IF(G9 <> "PAS",G9:H9,""))&(IF(Table1[[#This Row],[Sub-Area]]<>"",_xlfn.CONCAT("_",Table1[[#This Row],[Sub-Area]]),""))) -> LAR_CAR_PLC_AB_CtrLogix_61PLC_9347 | L9: =IF(I9 <> "",I9&":\PAS\CBR\ProcessedFiles\"&Table1[[#This Row],[Units]]&"\"&Table1[[#This Row],[Asset Type]]&"\"&K9,"") -> D:\PAS\CBR\ProcessedFiles\CAR\PLC\LAR_CAR_PLC_AB_CtrLogix_61PLC_9347 | M9: ="MKDIR "&Table1[[#This Row],[Suggested Folder Naming]] -> MKDIR D:\PAS\CBR\ProcessedFiles\CAR\PLC\LAR_CAR_PLC_AB_CtrLogix_61PLC_9347
B10: LAR | C10: CAR | D10: 61PLC_9348 | E10: PLC | F10: AB ControlLogix | G10: AB | H10: CtrLogix | I10: D | J10: =_xlfn.TEXTJOIN("_",TRUE,B10:C10) -> LAR_CAR | K10: =J10&"_"&E10&IF(ISNUMBER(SEARCH("PAS",G10)),"","_")&(_xlfn.TEXTJOIN("_",TRUE,IF(G10 <> "PAS",G10:H10,""))&(IF(Table1[[#This Row],[Sub-Area]]<>"",_xlfn.CONCAT("_",Table1[[#This Row],[Sub-Area]]),""))) -> LAR_CAR_PLC_AB_CtrLogix_61PLC_9348 | L10: =IF(I10 <> "",I10&":\PAS\CBR\ProcessedFiles\"&Table1[[#This Row],[Units]]&"\"&Table1[[#This Row],[Asset Type]]&"\"&K10,"") -> D:\PAS\CBR\ProcessedFiles\CAR\PLC\LAR_CAR_PLC_AB_CtrLogix_61PLC_9348 | M10: ="MKDIR "&Table1[[#This Row],[Suggested Folder Naming]] -> MKDIR D:\PAS\CBR\ProcessedFiles\CAR\PLC\LAR_CAR_PLC_AB_CtrLogix_61PLC_9348
B11: LAR | C11: CAR | D11: 70PLC_9318 | E11: PLC | F11: AB ControlLogix | G11: AB | H11: CtrLogix | I11: D | J11: =_xlfn.TEXTJOIN("_",TRUE,B11:C11) -> LAR_CAR | K11: =J11&"_"&E11&IF(ISNUMBER(SEARCH("PAS",G11)),"","_")&(_xlfn.TEXTJOIN("_",TRUE,IF(G11 <> "PAS",G11:H11,""))&(IF(Table1[[#This Row],[Sub-Area]]<>"",_xlfn.CONCAT("_",Table1[[#This Row],[Sub-Area]]),""))) -> LAR_CAR_PLC_AB_CtrLogix_70PLC_9318 | L11: =IF(I11 <> "",I11&":\PAS\CBR\ProcessedFiles\"&Table1[[#This Row],[Units]]&"\"&Table1[[#This Row],[Asset Type]]&"\"&K11,"") -> D:\PAS\CBR\ProcessedFiles\CAR\PLC\LAR_CAR_PLC_AB_CtrLogix_70PLC_9318 | M11: ="MKDIR "&Table1[[#This Row],[Suggested Folder Naming]] -> MKDIR D:\PAS\CBR\ProcessedFiles\CAR\PLC\LAR_CAR_PLC_AB_CtrLogix_70PLC_9318
B12: LAR | C12: CAR | D12: 70PLC_9325 | E12: PLC | F12: AB ControlLogix | G12: AB | H12: CtrLogix | I12: D | J12: =_xlfn.TEXTJOIN("_",TRUE,B12:C12) -> LAR_CAR | K12: =J12&"_"&E12&IF(ISNUMBER(SEARCH("PAS",G12)),"","_")&(_xlfn.TEXTJOIN("_",TRUE,IF(G12 <> "PAS",G12:H12,""))&(IF(Table1[[#This Row],[Sub-Area]]<>"",_xlfn.CONCAT("_",Table1[[#This Row],[Sub-Area]]),""))) -> LAR_CAR_PLC_AB_CtrLogix_70PLC_9325 | L12: =IF(I12 <> "",I12&":\PAS\CBR\ProcessedFiles\"&Table1[[#This Row],[Units]]&"\"&Table1[[#This Row],[Asset Type]]&"\"&K12,"") -> D:\PAS\CBR\ProcessedFiles\CAR\PLC\LAR_CAR_PLC_AB_CtrLogix_70PLC_9325 | M12: ="MKDIR "&Table1[[#This Row],[Suggested Folder Naming]] -> MKDIR D:\PAS\CBR\ProcessedFiles\CAR\PLC\LAR_CAR_PLC_AB_CtrLogix_70PLC_9325
B13: LAR | C13: CAR | D13: 73PLC_9330 | E13: PLC | F13: AB ControlLogix | G13: AB | H13: CtrLogix | I13: D | J13: =_xlfn.TEXTJOIN("_",TRUE,B13:C13) -> LAR_CAR | K13: =J13&"_"&E13&IF(ISNUMBER(SEARCH("PAS",G13)),"","_")&(_xlfn.TEXTJOIN("_",TRUE,IF(G13 <> "PAS",G13:H13,""))&(IF(Table1[[#This Row],[Sub-Area]]<>"",_xlfn.CONCAT("_",Table1[[#This Row],[Sub-Area]]),""))) -> LAR_CAR_PLC_AB_CtrLogix_73PLC_9330 | L13: =IF(I13 <> "",I13&":\PAS\CBR\ProcessedFiles\"&Table1[[#This Row],[Units]]&"\"&Table1[[#This Row],[Asset Type]]&"\"&K13,"") -> D:\PAS\CBR\ProcessedFiles\CAR\PLC\LAR_CAR_PLC_AB_CtrLogix_73PLC_9330 | M13: ="MKDIR "&Table1[[#This Row],[Suggested Folder Naming]] -> MKDIR D:\PAS\CBR\ProcessedFiles\CAR\PLC\LAR_CAR_PLC_AB_CtrLogix_73PLC_9330
B14: LAR | C14: CAR | D14: 74PLC_9338 | E14: PLC | F14: AB ControlLogix | G14: AB | H14: CtrLogix | I14: D | J14: =_xlfn.TEXTJOIN("_",TRUE,B14:C14) -> LAR_CAR | K14: =J14&"_"&E14&IF(ISNUMBER(SEARCH("PAS",G14)),"","_")&(_xlfn.TEXTJOIN("_",TRUE,IF(G14 <> "PAS",G14:H14,""))&(IF(Table1[[#This Row],[Sub-Area]]<>"",_xlfn.CONCAT("_",Table1[[#This Row],[Sub-Area]]),""))) -> LAR_CAR_PLC_AB_CtrLogix_74PLC_9338 | L14: =IF(I14 <> "",I14&":\PAS\CBR\ProcessedFiles\"&Table1[[#This Row],[Units]]&"\"&Table1[[#This Row],[Asset Type]]&"\"&K14,"") -> D:\PAS\CBR\ProcessedFiles\CAR\PLC\LAR_CAR_PLC_AB_CtrLogix_74PLC_9338 | M14: ="MKDIR "&Table1[[#This Row],[Suggested Folder Naming]] -> MKDIR D:\PAS\CBR\ProcessedFiles\CAR\PLC\LAR_CAR_PLC_AB_CtrLogix_74PLC_9338
B15: LAR | C15: CAR | D15: 75_PLC_9354 | E15: PLC | F15: AB ControlLogix | G15: =_xlfn.IFNA(VLOOKUP(F15,'Look Table'!B$1:E$64,3,FALSE),"") -> AB | H15: =_xlfn.IFNA(VLOOKUP(F15,'Look Table'!B$1:E$64,4,FALSE),"") -> CtrLogix | I15: D | J15: =_xlfn.TEXTJOIN("_",TRUE,B15:C15) -> LAR_CAR | K15: =J15&"_"&E15&IF(ISNUMBER(SEARCH("PAS",G15)),"","_")&(_xlfn.TEXTJOIN("_",TRUE,IF(G15 <> "PAS",G15:H15,""))&(IF(Table1[[#This Row],[Sub-Area]]<>"",_xlfn.CONCAT("_",Table1[[#This Row],[Sub-Area]]),""))) -> LAR_CAR_PLC_AB_CtrLogix_75_PLC_9354 | L15: =IF(I15 <> "",I15&":\PAS\CBR\ProcessedFiles\"&Table1[[#This Row],[Units]]&"\"&Table1[[#This Row],[Asset Type]]&"\"&K15,"") -> D:\PAS\CBR\ProcessedFiles\CAR\PLC\LAR_CAR_PLC_AB_CtrLogix_75_PLC_9354 | M15: ="MKDIR "&Table1[[#This Row],[Suggested Folder Naming]] -> MKDIR D:\PAS\CBR\ProcessedFiles\CAR\PLC\LAR_CAR_PLC_AB_CtrLogix_75_PLC_9354
B16: LAR | C16: CAR | D16: 75PLC_9333 | E16: PLC | F16: AB ControlLogix | G16: =_xlfn.IFNA(VLOOKUP(F16,'Look Table'!B$1:E$64,3,FALSE),"") -> AB | H16: =_xlfn.IFNA(VLOOKUP(F16,'Look Table'!B$1:E$64,4,FALSE),"") -> CtrLogix | I16: D | J16: =_xlfn.TEXTJOIN("_",TRUE,B16:C16) -> LAR_CAR | K16: =J16&"_"&E16&IF(ISNUMBER(SEARCH("PAS",G16)),"","_")&(_xlfn.TEXTJOIN("_",TRUE,IF(G16 <> "PAS",G16:H16,""))&(IF(Table1[[#This Row],[Sub-Area]]<>"",_xlfn.CONCAT("_",Table1[[#This Row],[Sub-Area]]),""))) -> LAR_CAR_PLC_AB_CtrLogix_75PLC_9333 | L16: =IF(I16 <> "",I16&":\PAS\CBR\ProcessedFiles\"&Table1[[#This Row],[Units]]&"\"&Table1[[#This Row],[Asset Type]]&"\"&K16,"") -> D:\PAS\CBR\ProcessedFiles\CAR\PLC\LAR_CAR_PLC_AB_CtrLogix_75PLC_9333 | M16: ="MKDIR "&Table1[[#This Row],[Suggested Folder Naming]] -> MKDIR D:\PAS\CBR\ProcessedFiles\CAR\PLC\LAR_CAR_PLC_AB_CtrLogix_75PLC_9333
B17: LAR | C17: CAR | D17: 80PLC_9052 | E17: PLC | F17: AB ControlLogix | G17: =_xlfn.IFNA(VLOOKUP(F17,'Look Table'!B$1:E$64,3,FALSE),"") -> AB | H17: =_xlfn.IFNA(VLOOKUP(F17,'Look Table'!B$1:E$64,4,FALSE),"") -> CtrLogix | I17: D | J17: =_xlfn.TEXTJOIN("_",TRUE,B17:C17) -> LAR_CAR | K17: =J17&"_"&E17&IF(ISNUMBER(SEARCH("PAS",G17)),"","_")&(_xlfn.TEXTJOIN("_",TRUE,IF(G17 <> "PAS",G17:H17,""))&(IF(Table1[[#This Row],[Sub-Area]]<>"",_xlfn.CONCAT("_",Table1[[#This Row],[Sub-Area]]),""))) -> LAR_CAR_PLC_AB_CtrLogix_80PLC_9052 | L17: =IF(I17 <> "",I17&":\PAS\CBR\ProcessedFiles\"&Table1[[#This Row],[Units]]&"\"&Table1[[#This Row],[Asset Type]]&"\"&K17,"") -> D:\PAS\CBR\ProcessedFiles\CAR\PLC\LAR_CAR_PLC_AB_CtrLogix_80PLC_9052 | M17: ="MKDIR "&Table1[[#This Row],[Suggested Folder Naming]] -> MKDIR D:\PAS\CBR\ProcessedFiles\CAR\PLC\LAR_CAR_PLC_AB_CtrLogix_80PLC_9052
B18: LAR | C18: CAR | D18: 82PLC_9332 | E18: PLC | F18: AB ControlLogix | G18: AB | H18: CtrLogix | I18: D | J18: =_xlfn.TEXTJOIN("_",TRUE,B18:C18) -> LAR_CAR | K18: =J18&"_"&E18&IF(ISNUMBER(SEARCH("PAS",G18)),"","_")&(_xlfn.TEXTJOIN("_",TRUE,IF(G18 <> "PAS",G18:H18,""))&(IF(Table1[[#This Row],[Sub-Area]]<>"",_xlfn.CONCAT("_",Table1[[#This Row],[Sub-Area]]),""))) -> LAR_CAR_PLC_AB_CtrLogix_82PLC_9332 | L18: =IF(I18 <> "",I18&":\PAS\CBR\ProcessedFiles\"&Table1[[#This Row],[Units]]&"\"&Table1[[#This Row],[Asset Type]]&"\"&K18,"") -> D:\PAS\CBR\ProcessedFiles\CAR\PLC\LAR_CAR_PLC_AB_CtrLogix_82PLC_9332 | M18: ="MKDIR "&Table1[[#This Row],[Suggested Folder Naming]] -> MKDIR D:\PAS\CBR\ProcessedFiles\CAR\PLC\LAR_CAR_PLC_AB_CtrLogix_82PLC_9332
B19: LAR | C19: CAR | D19: 84PLC_9308 | E19: PLC | F19: AB ControlLogix | G19: AB | H19: CtrLogix | I19: D | J19: =_xlfn.TEXTJOIN("_",TRUE,B19:C19) -> LAR_CAR | K19: =J19&"_"&E19&IF(ISNUMBER(SEARCH("PAS",G19)),"","_")&(_xlfn.TEXTJOIN("_",TRUE,IF(G19 <> "PAS",G19:H19,""))&(IF(Table1[[#This Row],[Sub-Area]]<>"",_xlfn.CONCAT("_",Table1[[#This Row],[Sub-Area]]),""))) -> LAR_CAR_PLC_AB_CtrLogix_84PLC_9308 | L19: =IF(I19 <> "",I19&":\PAS\CBR\ProcessedFiles\"&Table1[[#This Row],[Units]]&"\"&Table1[[#This Row],[Asset Type]]&"\"&K19,"") -> D:\PAS\CBR\ProcessedFiles\CAR\PLC\LAR_CAR_PLC_AB_CtrLogix_84PLC_9308 | M19: ="MKDIR "&Table1[[#This Row],[Suggested Folder Naming]] -> MKDIR D:\PAS\CBR\ProcessedFiles\CAR\PLC\LAR_CAR_PLC_AB_CtrLogix_84PLC_9308
B20: LAR | C20: CAR | D20: 84PLC_9309 | E20: PLC | F20: AB ControlLogix | G20: AB | H20: CtrLogix | I20: D | J20: =_xlfn.TEXTJOIN("_",TRUE,B20:C20) -> LAR_CAR | K20: =J20&"_"&E20&IF(ISNUMBER(SEARCH("PAS",G20)),"","_")&(_xlfn.TEXTJOIN("_",TRUE,IF(G20 <> "PAS",G20:H20,""))&(IF(Table1[[#This Row],[Sub-Area]]<>"",_xlfn.CONCAT("_",Table1[[#This Row],[Sub-Area]]),""))) -> LAR_CAR_PLC_AB_CtrLogix_84PLC_9309 | L20: =IF(I20 <> "",I20&":\PAS\CBR\ProcessedFiles\"&Table1[[#This Row],[Units]]&"\"&Table1[[#This Row],[Asset Type]]&"\"&K20,"") -> D:\PAS\CBR\ProcessedFiles\CAR\PLC\LAR_CAR_PLC_AB_CtrLogix_84PLC_9309 | M20: ="MKDIR "&Table1[[#This Row],[Suggested Folder Naming]] -> MKDIR D:\PAS\CBR\ProcessedFiles\CAR\PLC\LAR_CAR_PLC_AB_CtrLogix_84PLC_9309
B21: LAR | C21: CAR | D21: 84PLC_9310 | E21: PLC | F21: AB ControlLogix | G21: AB | H21: CtrLogix | I21: D | J21: =_xlfn.TEXTJOIN("_",TRUE,B21:C21) -> LAR_CAR | K21: =J21&"_"&E21&IF(ISNUMBER(SEARCH("PAS",G21)),"","_")&(_xlfn.TEXTJOIN("_",TRUE,IF(G21 <> "PAS",G21:H21,""))&(IF(Table1[[#This Row],[Sub-Area]]<>"",_xlfn.CONCAT("_",Table1[[#This Row],[Sub-Area]]),""))) -> LAR_CAR_PLC_AB_CtrLogix_84PLC_9310 | L21: =IF(I21 <> "",I21&":\PAS\CBR\ProcessedFiles\"&Table1[[#This Row],[Units]]&"\"&Table1[[#This Row],[Asset Type]]&"\"&K21,"") -> D:\PAS\CBR\ProcessedFiles\CAR\PLC\LAR_CAR_PLC_AB_CtrLogix_84PLC_9310 | M21: ="MKDIR "&Table1[[#This Row],[Suggested Folder Naming]] -> MKDIR D:\PAS\CBR\ProcessedFiles\CAR\PLC\LAR_CAR_PLC_AB_CtrLogix_84PLC_9310
B22: LAR | C22: CAR | D22: 84PLC_9311 | E22: PLC | F22: AB ControlLogix | G22: AB | H22: CtrLogix | I22: D | J22: =_xlfn.TEXTJOIN("_",TRUE,B22:C22) -> LAR_CAR | K22: =J22&"_"&E22&IF(ISNUMBER(SEARCH("PAS",G22)),"","_")&(_xlfn.TEXTJOIN("_",TRUE,IF(G22 <> "PAS",G22:H22,""))&(IF(Table1[[#This Row],[Sub-Area]]<>"",_xlfn.CONCAT("_",Table1[[#This Row],[Sub-Area]]),""))) -> LAR_CAR_PLC_AB_CtrLogix_84PLC_9311 | L22: =IF(I22 <> "",I22&":\PAS\CBR\ProcessedFiles\"&Table1[[#This Row],[Units]]&"\"&Table1[[#This Row],[Asset Type]]&"\"&K22,"") -> D:\PAS\CBR\ProcessedFiles\CAR\PLC\LAR_CAR_PLC_AB_CtrLogix_84PLC_9311 | M22: ="MKDIR "&Table1[[#This Row],[Suggested Folder Naming]] -> MKDIR D:\PAS\CBR\ProcessedFiles\CAR\PLC\LAR_CAR_PLC_AB_CtrLogix_84PLC_9311
B23: LAR | C23: CAR | D23: 84PLC_9312 | E23: PLC | F23: AB ControlLogix | G23: AB | H23: CtrLogix | I23: D | J23: =_xlfn.TEXTJOIN("_",TRUE,B23:C23) -> LAR_CAR | K23: =J23&"_"&E23&IF(ISNUMBER(SEARCH("PAS",G23)),"","_")&(_xlfn.TEXTJOIN("_",TRUE,IF(G23 <> "PAS",G23:H23,""))&(IF(Table1[[#This Row],[Sub-Area]]<>"",_xlfn.CONCAT("_",Table1[[#This Row],[Sub-Area]]),""))) -> LAR_CAR_PLC_AB_CtrLogix_84PLC_9312 | L23: =IF(I23 <> "",I23&":\PAS\CBR\ProcessedFiles\"&Table1[[#This Row],[Units]]&"\"&Table1[[#This Row],[Asset Type]]&"\"&K23,"") -> D:\PAS\CBR\ProcessedFiles\CAR\PLC\LAR_CAR_PLC_AB_CtrLogix_84PLC_9312 | M23: ="MKDIR "&Table1[[#This Row],[Suggested Folder Naming]] -> MKDIR D:\PAS\CBR\ProcessedFiles\CAR\PLC\LAR_CAR_PLC_AB_CtrLogix_84PLC_9312
B24: LAR | C24: CAR | D24: 87PLC_9340 | E24: PLC | F24: AB ControlLogix | G24: AB | H24: CtrLogix | I24: D | J24: =_xlfn.TEXTJOIN("_",TRUE,B24:C24) -> LAR_CAR | K24: =J24&"_"&E24&IF(ISNUMBER(SEARCH("PAS",G24)),"","_")&(_xlfn.TEXTJOIN("_",TRUE,IF(G24 <> "PAS",G24:H24,""))&(IF(Table1[[#This Row],[Sub-Area]]<>"",_xlfn.CONCAT("_",Table1[[#This Row],[Sub-Area]]),""))) -> LAR_CAR_PLC_AB_CtrLogix_87PLC_9340 | L24: =IF(I24 <> "",I24&":\PAS\CBR\ProcessedFiles\"&Table1[[#This Row],[Units]]&"\"&Table1[[#This Row],[Asset Type]]&"\"&K24,"") -> D:\PAS\CBR\ProcessedFiles\CAR\PLC\LAR_CAR_PLC_AB_CtrLogix_87PLC_9340 | M24: ="MKDIR "&Table1[[#This Row],[Suggested Folder Naming]] -> MKDIR D:\PAS\CBR\ProcessedFiles\CAR\PLC\LAR_CAR_PLC_AB_CtrLogix_87PLC_9340
B25: LAR | C25: CAR | D25: 88PLC_9329 | E25: PLC | F25: AB ControlLogix | G25: AB | H25: CtrLogix | I25: D | J25: =_xlfn.TEXTJOIN("_",TRUE,B25:C25) -> LAR_CAR | K25: =J25&"_"&E25&IF(ISNUMBER(SEARCH("PAS",G25)),"","_")&(_xlfn.TEXTJOIN("_",TRUE,IF(G25 <> "PAS",G25:H25,""))&(IF(Table1[[#This Row],[Sub-Area]]<>"",_xlfn.CONCAT("_",Table1[[#This Row],[Sub-Area]]),""))) -> LAR_CAR_PLC_AB_CtrLogix_88PLC_9329 | L25: =IF(I25 <> "",I25&":\PAS\CBR\ProcessedFiles\"&Table1[[#This Row],[Units]]&"\"&Table1[[#This Row],[Asset Type]]&"\"&K25,"") -> D:\PAS\CBR\ProcessedFiles\CAR\PLC\LAR_CAR_PLC_AB_CtrLogix_88PLC_9329 | M25: ="MKDIR "&Table1[[#This Row],[Suggested Folder Naming]] -> MKDIR D:\PAS\CBR\ProcessedFiles\CAR\PLC\LAR_CAR_PLC_AB_CtrLogix_88PLC_9329
B26: LAR | C26: CAR | D26: 98PLC_9327 | E26: PLC | F26: AB ControlLogix | G26: AB | H26: CtrLogix | I26: D | J26: =_xlfn.TEXTJOIN("_",TRUE,B26:C26) -> LAR_CAR | K26: =J26&"_"&E26&IF(ISNUMBER(SEARCH("PAS",G26)),"","_")&(_xlfn.TEXTJOIN("_",TRUE,IF(G26 <> "PAS",G26:H26,""))&(IF(Table1[[#This Row],[Sub-Area]]<>"",_xlfn.CONCAT("_",Table1[[#This Row],[Sub-Area]]),""))) -> LAR_CAR_PLC_AB_CtrLogix_98PLC_9327 | L26: =IF(I26 <> "",I26&":\PAS\CBR\ProcessedFiles\"&Table1[[#This Row],[Units]]&"\"&Table1[[#This Row],[Asset Type]]&"\"&K26,"") -> D:\PAS\CBR\ProcessedFiles\CAR\PLC\LAR_CAR_PLC_AB_CtrLogix_98PLC_9327 | M26: ="MKDIR "&Table1[[#This Row],[Suggested Folder Naming]] -> MKDIR D:\PAS\CBR\ProcessedFiles\CAR\PLC\LAR_CAR_PLC_AB_CtrLogix_98PLC_9327
B27: LAR | C27: CAR | D27: 98PLC_9328 | E27: PLC | F27: AB ControlLogix | G27: AB | H27: CtrLogix | I27: D | J27: =_xlfn.TEXTJOIN("_",TRUE,B27:C27) -> LAR_CAR | K27: =J27&"_"&E27&IF(ISNUMBER(SEARCH("PAS",G27)),"","_")&(_xlfn.TEXTJOIN("_",TRUE,IF(G27 <> "PAS",G27:H27,""))&(IF(Table1[[#This Row],[Sub-Area]]<>"",_xlfn.CONCAT("_",Table1[[#This Row],[Sub-Area]]),""))) -> LAR_CAR_PLC_AB_CtrLogix_98PLC_9328 | L27: =IF(I27 <> "",I27&":\PAS\CBR\ProcessedFiles\"&Table1[[#This Row],[Units]]&"\"&Table1[[#This Row],[Asset Type]]&"\"&K27,"") -> D:\PAS\CBR\ProcessedFiles\CAR\PLC\LAR_CAR_PLC_AB_CtrLogix_98PLC_9328 | M27: ="MKDIR "&Table1[[#This Row],[Suggested Folder Naming]] -> MKDIR D:\PAS\CBR\ProcessedFiles\CAR\PLC\LAR_CAR_PLC_AB_CtrLogix_98PLC_9328
B28: LAR | C28: CAR | D28: ANLZ_03PLC_9316 | E28: PLC | F28: AB ControlLogix | G28: =_xlfn.IFNA(VLOOKUP(F28,'[1]Look Table'!B$1:E$75,3,FALSE),"") -> AB | H28: =_xlfn.IFNA(VLOOKUP(F28,'[1]Look Table'!B$1:E$75,4,FALSE),"") -> CtrLogix | I28: D | J28: =_xlfn.TEXTJOIN("_",TRUE,B28:C28) -> LAR_CAR | K28: =J28&"_"&E28&IF(ISNUMBER(SEARCH("PAS",G28)),"","_")&(_xlfn.TEXTJOIN("_",TRUE,IF(G28 <> "PAS",G28:H28,""))&(IF(Table1[[#This Row],[Sub-Area]]<>"",_xlfn.CONCAT("_",Table1[[#This Row],[Sub-Area]]),""))) -> LAR_CAR_PLC_AB_CtrLogix_ANLZ_03PLC_9316 | L28: =IF(I28 <> "",I28&":\PAS\CBR\ProcessedFiles\"&Table1[[#This Row],[Units]]&"\"&Table1[[#This Row],[Asset Type]]&"\"&K28,"") -> D:\PAS\CBR\ProcessedFiles\CAR\PLC\LAR_CAR_PLC_AB_CtrLogix_ANLZ_03PLC_9316 | M28: ="MKDIR "&Table1[[#This Row],[Suggested Folder Naming]] -> MKDIR D:\PAS\CBR\ProcessedFiles\CAR\PLC\LAR_CAR_PLC_AB_CtrLogix_ANLZ_03PLC_9316
B29: LAR | C29: CAR | D29: ANLZ_03PLC_9322 | E29: PLC | F29: AB ControlLogix | G29: =_xlfn.IFNA(VLOOKUP(F29,'[1]Look Table'!B$1:E$75,3,FALSE),"") -> AB | H29: =_xlfn.IFNA(VLOOKUP(F29,'[1]Look Table'!B$1:E$75,4,FALSE),"") -> CtrLogix | I29: D | J29: =_xlfn.TEXTJOIN("_",TRUE,B29:C29) -> LAR_CAR | K29: =J29&"_"&E29&IF(ISNUMBER(SEARCH("PAS",G29)),"","_")&(_xlfn.TEXTJOIN("_",TRUE,IF(G29 <> "PAS",G29:H29,""))&(IF(Table1[[#This Row],[Sub-Area]]<>"",_xlfn.CONCAT("_",Table1[[#This Row],[Sub-Area]]),""))) -> LAR_CAR_PLC_AB_CtrLogix_ANLZ_03PLC_9322 | L29: =IF(I29 <> "",I29&":\PAS\CBR\ProcessedFiles\"&Table1[[#This Row],[Units]]&"\"&Table1[[#This Row],[Asset Type]]&"\"&K29,"") -> D:\PAS\CBR\ProcessedFiles\CAR\PLC\LAR_CAR_PLC_AB_CtrLogix_ANLZ_03PLC_9322 | M29: ="MKDIR "&Table1[[#This Row],[Suggested Folder Naming]] -> MKDIR D:\PAS\CBR\ProcessedFiles\CAR\PLC\LAR_CAR_PLC_AB_CtrLogix_ANLZ_03PLC_9322
B30: LAR | C30: CAR | D30: ANLZ_11PLC_9315 | E30: PLC | F30: AB ControlLogix | G30: =_xlfn.IFNA(VLOOKUP(F30,'[1]Look Table'!B$1:E$75,3,FALSE),"") -> AB | H30: =_xlfn.IFNA(VLOOKUP(F30,'[1]Look Table'!B$1:E$75,4,FALSE),"") -> CtrLogix | I30: D | J30: =_xlfn.TEXTJOIN("_",TRUE,B30:C30) -> LAR_CAR | K30: =J30&"_"&E30&IF(ISNUMBER(SEARCH("PAS",G30)),"","_")&(_xlfn.TEXTJOIN("_",TRUE,IF(G30 <> "PAS",G30:H30,""))&(IF(Table1[[#This Row],[Sub-Area]]<>"",_xlfn.CONCAT("_",Table1[[#This Row],[Sub-Area]]),""))) -> LAR_CAR_PLC_AB_CtrLogix_ANLZ_11PLC_9315 | L30: =IF(I30 <> "",I30&":\PAS\CBR\ProcessedFiles\"&Table1[[#This Row],[Units]]&"\"&Table1[[#This Row],[Asset Type]]&"\"&K30,"") -> D:\PAS\CBR\ProcessedFiles\CAR\PLC\LAR_CAR_PLC_AB_CtrLogix_ANLZ_11PLC_9315 | M30: ="MKDIR "&Table1[[#This Row],[Suggested Folder Naming]] -> MKDIR D:\PAS\CBR\ProcessedFiles\CAR\PLC\LAR_CAR_PLC_AB_CtrLogix_ANLZ_11PLC_9315
B31: LAR | C31: CAR | D31: ANLZ_11PLC_9324 | E31: PLC | F31: AB ControlLogix | G31: =_xlfn.IFNA(VLOOKUP(F31,'[1]Look Table'!B$1:E$75,3,FALSE),"") -> AB | H31: =_xlfn.IFNA(VLOOKUP(F31,'[1]Look Table'!B$1:E$75,4,FALSE),"") -> CtrLogix | I31: D | J31: =_xlfn.TEXTJOIN("_",TRUE,B31:C31) -> LAR_CAR | K31: =J31&"_"&E31&IF(ISNUMBER(SEARCH("PAS",G31)),"","_")&(_xlfn.TEXTJOIN("_",TRUE,IF(G31 <> "PAS",G31:H31,""))&(IF(Table1[[#This Row],[Sub-Area]]<>"",_xlfn.CONCAT("_",Table1[[#This Row],[Sub-Area]]),""))) -> LAR_CAR_PLC_AB_CtrLogix_ANLZ_11PLC_9324 | L31: =IF(I31 <> "",I31&":\PAS\CBR\ProcessedFiles\"&Table1[[#This Row],[Units]]&"\"&Table1[[#This Row],[Asset Type]]&"\"&K31,"") -> D:\PAS\CBR\ProcessedFiles\CAR\PLC\LAR_CAR_PLC_AB_CtrLogix_ANLZ_11PLC_9324 | M31: ="MKDIR "&Table1[[#This Row],[Suggested Folder Naming]] -> MKDIR D:\PAS\CBR\ProcessedFiles\CAR\PLC\LAR_CAR_PLC_AB_CtrLogix_ANLZ_11PLC_9324
B32: LAR | C32: CAR | D32: ANLZ_23PLC_9317 | E32: PLC | F32: AB ControlLogix | G32: =_xlfn.IFNA(VLOOKUP(F32,'[1]Look Table'!B$1:E$75,3,FALSE),"") -> AB | H32: =_xlfn.IFNA(VLOOKUP(F32,'[1]Look Table'!B$1:E$75,4,FALSE),"") -> CtrLogix | I32: D | J32: =_xlfn.TEXTJOIN("_",TRUE,B32:C32) -> LAR_CAR | K32: =J32&"_"&E32&IF(ISNUMBER(SEARCH("PAS",G32)),"","_")&(_xlfn.TEXTJOIN("_",TRUE,IF(G32 <> "PAS",G32:H32,""))&(IF(Table1[[#This Row],[Sub-Area]]<>"",_xlfn.CONCAT("_",Table1[[#This Row],[Sub-Area]]),""))) -> LAR_CAR_PLC_AB_CtrLogix_ANLZ_23PLC_9317 | L32: =IF(I32 <> "",I32&":\PAS\CBR\ProcessedFiles\"&Table1[[#This Row],[Units]]&"\"&Table1[[#This Row],[Asset Type]]&"\"&K32,"") -> D:\PAS\CBR\ProcessedFiles\CAR\PLC\LAR_CAR_PLC_AB_CtrLogix_ANLZ_23PLC_9317 | M32: ="MKDIR "&Table1[[#This Row],[Suggested Folder Naming]] -> MKDIR D:\PAS\CBR\ProcessedFiles\CAR\PLC\LAR_CAR_PLC_AB_CtrLogix_ANLZ_23PLC_9317
B33: LAR | C33: CAR | D33: ANLZ_23PLC_9323 | E33: PLC | F33: AB ControlLogix | G33: =_xlfn.IFNA(VLOOKUP(F33,'[1]Look Table'!B$1:E$75,3,FALSE),"") -> AB | H33: =_xlfn.IFNA(VLOOKUP(F33,'[1]Look Table'!B$1:E$75,4,FALSE),"") -> CtrLogix | I33: D | J33: =_xlfn.TEXTJOIN("_",TRUE,B33:C33) -> LAR_CAR | K33: =J33&"_"&E33&IF(ISNUMBER(SEARCH("PAS",G33)),"","_")&(_xlfn.TEXTJOIN("_",TRUE,IF(G33 <> "PAS",G33:H33,""))&(IF(Table1[[#This Row],[Sub-Area]]<>"",_xlfn.CONCAT("_",Table1[[#This Row],[Sub-Area]]),""))) -> LAR_CAR_PLC_AB_CtrLogix_ANLZ_23PLC_9323 | L33: =IF(I33 <> "",I33&":\PAS\CBR\ProcessedFiles\"&Table1[[#This Row],[Units]]&"\"&Table1[[#This Row],[Asset Type]]&"\"&K33,"") -> D:\PAS\CBR\ProcessedFiles\CAR\PLC\LAR_CAR_PLC_AB_CtrLogix_ANLZ_23PLC_9323 | M33: ="MKDIR "&Table1[[#This Row],[Suggested Folder Naming]] -> MKDIR D:\PAS\CBR\ProcessedFiles\CAR\PLC\LAR_CAR_PLC_AB_CtrLogix_ANLZ_23PLC_9323
B34: LAR | C34: CAR | D34: ANLZ_70PLC_9313 | E34: PLC | F34: AB ControlLogix | G34: =_xlfn.IFNA(VLOOKUP(F34,'[1]Look Table'!B$1:E$75,3,FALSE),"") -> AB | H34: =_xlfn.IFNA(VLOOKUP(F34,'[1]Look Table'!B$1:E$75,4,FALSE),"") -> CtrLogix | I34: D | J34: =_xlfn.TEXTJOIN("_",TRUE,B34:C34) -> LAR_CAR | K34: =J34&"_"&E34&IF(ISNUMBER(SEARCH("PAS",G34)),"","_")&(_xlfn.TEXTJOIN("_",TRUE,IF(G34 <> "PAS",G34:H34,""))&(IF(Table1[[#This Row],[Sub-Area]]<>"",_xlfn.CONCAT("_",Table1[[#This Row],[Sub-Area]]),""))) -> LAR_CAR_PLC_AB_CtrLogix_ANLZ_70PLC_9313 | L34: =IF(I34 <> "",I34&":\PAS\CBR\ProcessedFiles\"&Table1[[#This Row],[Units]]&"\"&Table1[[#This Row],[Asset Type]]&"\"&K34,"") -> D:\PAS\CBR\ProcessedFiles\CAR\PLC\LAR_CAR_PLC_AB_CtrLogix_ANLZ_70PLC_9313 | M34: ="MKDIR "&Table1[[#This Row],[Suggested Folder Naming]] -> MKDIR D:\PAS\CBR\ProcessedFiles\CAR\PLC\LAR_CAR_PLC_AB_CtrLogix_ANLZ_70PLC_9313
B35: LAR | C35: CAR | D35: ANLZ_73PLC_9307 | E35: PLC | F35: AB ControlLogix | G35: =_xlfn.IFNA(VLOOKUP(F35,'[1]Look Table'!B$1:E$75,3,FALSE),"") -> AB | H35: =_xlfn.IFNA(VLOOKUP(F35,'[1]Look Table'!B$1:E$75,4,FALSE),"") -> CtrLogix | I35: D | J35: =_xlfn.TEXTJOIN("_",TRUE,B35:C35) -> LAR_CAR | K35: =J35&"_"&E35&IF(ISNUMBER(SEARCH("PAS",G35)),"","_")&(_xlfn.TEXTJOIN("_",TRUE,IF(G35 <> "PAS",G35:H35,""))&(IF(Table1[[#This Row],[Sub-Area]]<>"",_xlfn.CONCAT("_",Table1[[#This Row],[Sub-Area]]),""))) -> LAR_CAR_PLC_AB_CtrLogix_ANLZ_73PLC_9307 | L35: =IF(I35 <> "",I35&":\PAS\CBR\ProcessedFiles\"&Table1[[#This Row],[Units]]&"\"&Table1[[#This Row],[Asset Type]]&"\"&K35,"") -> D:\PAS\CBR\ProcessedFiles\CAR\PLC\LAR_CAR_PLC_AB_CtrLogix_ANLZ_73PLC_9307 | M35: ="MKDIR "&Table1[[#This Row],[Suggested Folder Naming]] -> MKDIR D:\PAS\CBR\ProcessedFiles\CAR\PLC\LAR_CAR_PLC_AB_CtrLogix_ANLZ_73PLC_9307
B36: LAR | C36: CAR | D36: ANLZ_80PLC_9314 | E36: PLC | F36: AB ControlLogix | G36: =_xlfn.IFNA(VLOOKUP(F36,'[1]Look Table'!B$1:E$75,3,FALSE),"") -> AB | H36: =_xlfn.IFNA(VLOOKUP(F36,'[1]Look Table'!B$1:E$75,4,FALSE),"") -> CtrLogix | I36: D | J36: =_xlfn.TEXTJOIN("_",TRUE,B36:C36) -> LAR_CAR | K36: =J36&"_"&E36&IF(ISNUMBER(SEARCH("PAS",G36)),"","_")&(_xlfn.TEXTJOIN("_",TRUE,IF(G36 <> "PAS",G36:H36,""))&(IF(Table1[[#This Row],[Sub-Area]]<>"",_xlfn.CONCAT("_",Table1[[#This Row],[Sub-Area]]),""))) -> LAR_CAR_PLC_AB_CtrLogix_ANLZ_80PLC_9314 | L36: =IF(I36 <> "",I36&":\PAS\CBR\ProcessedFiles\"&Table1[[#This Row],[Units]]&"\"&Table1[[#This Row],[Asset Type]]&"\"&K36,"") -> D:\PAS\CBR\ProcessedFiles\CAR\PLC\LAR_CAR_PLC_AB_CtrLogix_ANLZ_80PLC_9314 | M36: ="MKDIR "&Table1[[#This Row],[Suggested Folder Naming]] -> MKDIR D:\PAS\CBR\ProcessedFiles\CAR\PLC\LAR_CAR_PLC_AB_CtrLogix_ANLZ_80PLC_9314
B37: LAR | C37: CAR | D37: ANLZ_80PLC_9321 | E37: PLC | F37: AB ControlLogix | G37: =_xlfn.IFNA(VLOOKUP(F37,'[1]Look Table'!B$1:E$75,3,FALSE),"") -> AB | H37: =_xlfn.IFNA(VLOOKUP(F37,'[1]Look Table'!B$1:E$75,4,FALSE),"") -> CtrLogix | I37: D | J37: =_xlfn.TEXTJOIN("_",TRUE,B37:C37) -> LAR_CAR | K37: =J37&"_"&E37&IF(ISNUMBER(SEARCH("PAS",G37)),"","_")&(_xlfn.TEXTJOIN("_",TRUE,IF(G37 <> "PAS",G37:H37,""))&(IF(Table1[[#This Row],[Sub-Area]]<>"",_xlfn.CONCAT("_",Table1[[#This Row],[Sub-Area]]),""))) -> LAR_CAR_PLC_AB_CtrLogix_ANLZ_80PLC_9321 | L37: =IF(I37 <> "",I37&":\PAS\CBR\ProcessedFiles\"&Table1[[#This Row],[Units]]&"\"&Table1[[#This Row],[Asset Type]]&"\"&K37,"") -> D:\PAS\CBR\ProcessedFiles\CAR\PLC\LAR_CAR_PLC_AB_CtrLogix_ANLZ_80PLC_9321 | M37: ="MKDIR "&Table1[[#This Row],[Suggested Folder Naming]] -> MKDIR D:\PAS\CBR\ProcessedFiles\CAR\PLC\LAR_CAR_PLC_AB_CtrLogix_ANLZ_80PLC_9321
B38: LAR | C38: CAR | D38: ANLZ_84PLC_9319 | E38: PLC | F38: AB ControlLogix | G38: =_xlfn.IFNA(VLOOKUP(F38,'[1]Look Table'!B$1:E$75,3,FALSE),"") -> AB | H38: =_xlfn.IFNA(VLOOKUP(F38,'[1]Look Table'!B$1:E$75,4,FALSE),"") -> CtrLogix | I38: D | J38: =_xlfn.TEXTJOIN("_",TRUE,B38:C38) -> LAR_CAR | K38: =J38&"_"&E38&IF(ISNUMBER(SEARCH("PAS",G38)),"","_")&(_xlfn.TEXTJOIN("_",TRUE,IF(G38 <> "PAS",G38:H38,""))&(IF(Table1[[#This Row],[Sub-Area]]<>"",_xlfn.CONCAT("_",Table1[[#This Row],[Sub-Area]]),""))) -> LAR_CAR_PLC_AB_CtrLogix_ANLZ_84PLC_9319 | L38: =IF(I38 <> "",I38&":\PAS\CBR\ProcessedFiles\"&Table1[[#This Row],[Units]]&"\"&Table1[[#This Row],[Asset Type]]&"\"&K38,"") -> D:\PAS\CBR\ProcessedFiles\CAR\PLC\LAR_CAR_PLC_AB_CtrLogix_ANLZ_84PLC_9319 | M38: ="MKDIR "&Table1[[#This Row],[Suggested Folder Naming]] -> MKDIR D:\PAS\CBR\ProcessedFiles\CAR\PLC\LAR_CAR_PLC_AB_CtrLogix_ANLZ_84PLC_9319
B39: LAR | C39: WCC | D39: ANLZ_03PLC_9336 | E39: PLC | F39: AB ControlLogix | G39: =_xlfn.IFNA(VLOOKUP(F39,'[1]Look Table'!B$1:E$75,3,FALSE),"") -> AB | H39: =_xlfn.IFNA(VLOOKUP(F39,'[1]Look Table'!B$1:E$75,4,FALSE),"") -> CtrLogix | I39: D | J39: =_xlfn.TEXTJOIN("_",TRUE,B39:C39) -> LAR_WCC | K39: =J39&"_"&E39&IF(ISNUMBER(SEARCH("PAS",G39)),"","_")&(_xlfn.TEXTJOIN("_",TRUE,IF(G39 <> "PAS",G39:H39,""))&(IF(Table1[[#This Row],[Sub-Area]]<>"",_xlfn.CONCAT("_",Table1[[#This Row],[Sub-Area]]),""))) -> LAR_WCC_PLC_AB_CtrLogix_ANLZ_03PLC_9336 | L39: =IF(I39 <> "",I39&":\PAS\CBR\ProcessedFiles\"&Table1[[#This Row],[Units]]&"\"&Table1[[#This Row],[Asset Type]]&"\"&K39,"") -> D:\PAS\CBR\ProcessedFiles\WCC\PLC\LAR_WCC_PLC_AB_CtrLogix_ANLZ_03PLC_9336 | M39: ="MKDIR "&Table1[[#This Row],[Suggested Folder Naming]] -> MKDIR D:\PAS\CBR\ProcessedFiles\WCC\PLC\LAR_WCC_PLC_AB_CtrLogix_ANLZ_03PLC_9336
... B61: LAR | C61: WCC | D61: ANLZ_Cogen_Fuel_Gas_GC_PLC | E61: PLC | F61: AB ControlLogix | G61: =_xlfn.IFNA(VLOOKUP(F61,'[1]Look Table'!B$1:E$75,3,FALSE),"") -> AB | H61: =_xlfn.IFNA(VLOOKUP(F61,'[1]Look Table'!B$1:E$75,4,FALSE),"") -> CtrLogix | I61: D | J61: =_xlfn.TEXTJOIN("_",TRUE,B61:C61) -> LAR_WCC | K61: =J61&"_"&E61&IF(ISNUMBER(SEARCH("PAS",G61)),"","_")&(_xlfn.TEXTJOIN("_",TRUE,IF(G61 <> "PAS",G61:H61,""))&(IF(Table1[[#This Row],[Sub-Area]]<>"",_xlfn.CONCAT("_",Table1[[#This Row],[Sub-Area]]),""))) -> LAR_WCC_PLC_AB_CtrLogix_ANLZ_Cogen_Fuel_Gas_GC_PLC | L61: =IF(I61 <> "",I61&":\PAS\CBR\ProcessedFiles\"&Table1[[#This Row],[Units]]&"\"&Table1[[#This Row],[Asset Type]]&"\"&K61,"") -> D:\PAS\CBR\ProcessedFiles\WCC\PLC\LAR_WCC_PLC_AB_CtrLogix_ANLZ_Cogen_Fuel_Gas_GC_PLC | M61: ="MKDIR "&Table1[[#This Row],[Suggested Folder Naming]] -> MKDIR D:\PAS\CBR\ProcessedFiles\WCC\PLC\LAR_WCC_PLC_AB_CtrLogix_ANLZ_Cogen_Fuel_Gas_GC_PLC
...

Sheet Sheet1
D1: qdeadadada
D2: LAR_CAR_ManualInventory
D3: LAR_WCC_ManualInventory
D4: LAR_WIL_ManualInventory
D5: LAR_CAR_PLC_AB_CtrLogix_17PLC_9057
D6: LAR_CAR_PLC_AB_CtrLogix_61PLC_9337
D7: LAR_CAR_PLC_AB_CtrLogix_61PLC_9347
D8: LAR_CAR_PLC_AB_CtrLogix_61PLC_9348
D9: LAR_CAR_PLC_AB_CtrLogix_70PLC_9318
D10: LAR_CAR_PLC_AB_CtrLogix_70PLC_9325
D11: LAR_CAR_PLC_AB_CtrLogix_73PLC_9330
D12: LAR_CAR_PLC_AB_CtrLogix_74PLC_9338
... D380: LAR_WIL_TCS_Woodward_GAP_Cogen_STG

Sheet Look Table
A1: Asset Type | B1: Asset Model | C1: Vendor | D1: Vendor Prefix | E1: Product
A2: APC | B2: Aspen DMCplus | C2: Aspen | D2: Aspen | E2: DMCplus
A3: DCS | B3: ABB Freelance | C3: ABB | D3: =C3 -> ABB | E3: Freelance
A4: DCS | B4: ABB Harmony | C4: ABB | D4: =C4 -> ABB | E4: Harmony
A5: DCS | B5: ABB Symphony Plus | C5: ABB | D5: =C5 -> ABB | E5: SymphonyPlus
A6: DCS | B6: Dow MOD5 | C6: Dow | D6: =C6 -> Dow | E6: MOD5
A7: DCS | B7: Emerson DeltaV | C7: Emerson | D7: EE | E7: DeltaV
A8: DCS | B8: Emerson Ovation | C8: Emerson | D8: EE | E8: Ovation
A9: DCS | B9: Honeywell EPKS | C9: Honeywell | D9: HW | E9: EPKS
A10: DCS | B10: Honeywell TPS | C10: Honeywell | D10: HW | E10: TPS
A11: DCS | B11: Invensys CTS | C11: Schneider | D11: SE | E11: CTS
A12: DCS | B12: Invensys FoxIA | C12: Schneider | D12: SE | E12: FoxIA
A13: DCS | B13: Invensys Infusion | C13: Schneider | D13: SE | E13: Infusion
A14: DCS | B14: Schneider Foxboro Evo | C14: Schneider | D14: SE | E14: FoxboroEvo
A15: DCS | B15: Siemens PCS7 | C15: Siemens | D15: SI | E15: PCS7
A16: DCS | B16: Siemens T3000 | C16: Siemens | D16: SI | E16: T3000
A17: DCS | B17: Yokogawa Centum CS3000 | C17: Yokogawa | D17: YKGW | E17: CentumCS3000
A18: DCS | B18: Yokogawa Centum VP | C18: Yokogawa | D18: YKGW | E18: CentumVP
A19: ManualInventory | B19: [Manual-Inventory] | C19: PAS | D19: =C19 -> PAS | E19: ManualInventory
A20: Historian | B20: Aspen IP21 | C20: Aspen | D20: AZPN | E20: IP21
A21: Historian | B21: OSISoft PI | C21: OSI | D21: =C21 -> OSI | E21: PI
A22: Historian | B22: HW PHD | C22: HWL | D22: =C22 -> HWL | E22: PHD
A23: HMI | B23: WonderWare InTouch | C23: Schneider | D23: SE | E23: InTouch
A24: MISC | B24: GE Alspa | C24: GE | D24: =C24 -> GE | E24: Alspa
A25: MISC | B25: HIMA ELOP II | C25: HIMA | D25: =C25 -> HIMA | E25: ELOPII
A26: MISC | B26: Honeywell Intuition Executive | C26: Honeywell | D26: HWL | E26: IntuitionExecutive
A27: MISC | B27: Honeywell Intuition Forms | C27: Honeywell | D27: HWL | E27: IntuitionForms
A28: MISC | B28: Honeywell RMPCT | C28: Honeywell | D28: HWL | E28: RMPCT
A29: MISC | B29: HWL PHD | C29: Honeywell | D29: HWL | E29: PHD
A30: MISC | B30: Intergraph INtools | C30: Integraph | D30: =C30 -> Integraph | E30: INtools
A31: MISC | B31: Intergraph Smart Instrumentation | C31: Integraph | D31: =C31 -> Integraph | E31: SmartIntrument
A32: MISC | B32: PAS Sensor Data Integrity | C32: PAS | D32: PAS | E32: SDI
A33: MISC | B33: SKF Aptitude Observer | C33: SKF | D33: =C33 -> SKF | E33: AptitudeObserver
A34: MISC | B34: Woodward GAP | C34: Woodward | D34: =C34 -> Woodward | E34: GAP
A35: NetworkDevices | B35: PAS Network Devices | C35: PAS | D35: =C35 -> PAS | E35: NetworkDevices
A36: NetworkDevices | B36: SNMP Network Devices | C36: PAS | D36: =C36 -> PAS | E36: SNMP_NetworkDevices
A37: Recon | B37: PAS Recon | C37: PAS | D37: =C37 -> PAS | E37: Recon
A38: PLC | B38: AB ControlLogix | C38: AB | D38: =C38 -> AB | E38: CtrLogix
A39: PLC | B39: AB PLC5 | C39: AB | D39: =C39 -> AB | E39: PLC5
A40: PLC | B40: AB SLC500 | C40: AB | D40: =C40 -> AB | E40: SLC500
...

Sheet Selections
A1: Asset Type | B1: Drive | C1: DCS Models | D1: Manual Models | E1: MISC Models | F1: NetworkDevices Models | G1: PLC Models | H1: Recon Models | I1: RTU Models | J1: SCADA Models | K1: SIS Models | L1: TCS Models | M1: VMS Models | N1: APC Models | O1: FGS Models | P1: Historian Models
A3: DCS | B3: C | C3: ABB 800xA | D3: [Manual-Inventory] | E3: Honeywell Intuition Executive | F3: PAS Network Devices | G3: AB ControlLogix | H3: PAS Recon | I3: Schweitzer Relays | J3: GE Cimplicity | K3: Honeywell FSC | L3: GE Mark V | M3: Bently Nevada 3500 | N3: Aspen DMCplus | O3: GE Cimplicity | P3: Aspen IP21
A4: NetworkDevices | B4: D | C4: ABB Freelance | E4: Honeywell Intuition Forms | F4: SNMP Network Devices | G4: AB PLC5 | J4: WonderWare InTouch | K4: Honeywell LM | L4: GE Mark VI | M4: SKF Aptitude Observer | N4: Honeywell RMPCT | O4: Honeywell SM | P4: HW PHD
A5: Recon | B5: E | C5: ABB Harmony | E5: Intergraph INtools | G5: AB SLC500 | J5: GE Proficy ME | K5: Honeywell SM | L5: GE Mark VIe | M5: GE Cimplicity | N5: Honeywell AFM | O5: Yokogawa Prosafe RS | P5: OSISoft PI
A6: SIS | B6: F | C6: ABB Symphony Plus | E6: Intergraph Smart Instrumentation | G6: GE Fanuc 90 | J6: GE Alspa | K6: ICS Triplex Trusted | L6: Woodward GAP | N6: Honeywell BCM | O6: Triconex TS1131 | P6: PAS PlantState Configuration
A7: PLC | B7: G | C7: Emerson DeltaV | E7: Emerson – AMS | G7: GE Proficy ME | K7: Triconex MSW | L7: Triconex TS1131 | N7: Aspen IQ | O7: HIMA ELOP II
A8: VMS | B8: H | C8: Emerson Ovation | E8: Honeywell FDM | G8: Rockwell FactoryTalk AssetCentre | K8: Triconex TS1131 | L8: GE Alspa | O8: WonderWare InTouch
A9: FGS | C9: Honeywell EPKS | E9: PAS Sensor Data Integrity | G9: Rockwell Studio 5000 | K9: Yokogawa Prosafe RS
A10: TCS | C10: Honeywell TPS | E10: Yokogawa PRM | G10: Modicon Proworx | K10: HIMA ELOP II
A11: Historian | C11: Invensys CTS | G11: Modicon ProWorx32
A12: APC | C12: Invensys FoxIA | G12: Siemens S7 400
A13: ManualInventory | C13: Invensys Infusion | G13: Siemens TIA Portal
A14: SCADA | C14: Schneider Foxboro Evo | G14: Schneider Unity Pro
A15: RTU | C15: Siemens PCS7
A16: MISC | C16: Siemens T3000
C17: Yokogawa Centum CS3000
C18: Yokogawa Centum VP
